<?xml version="1.0" ?>
<sdf version="1.4">
  <world name="default">
    <physics type="ode">
      <gravity>0.0 0.0 -9.81</gravity>
      <ode>
        <solver>
          <type>quick</type>
        </solver>
      </ode>
      <real_time_update_rate>100</real_time_update_rate>
      <max_step_size>0.001</max_step_size>
    </physics>
    <include>
      <uri>model://sun</uri>
    </include>
    <include>
      <uri>model://ground_plane</uri>
    </include>

    <model name="wind_demo_model">
      <pose>0.5 0 0 0 0 0</pose>
      <static>false</static>
      <enable_wind>true</enable_wind>
      <self_collide>false</self_collide>
      <link name="roof">
        <kinematic>true</kinematic>
        <pose>0 0 1 0 0 0</pose>
        <visual name="visual">
          <transparency>1</transparency>
          <geometry>
            <box>
              <size>0.05 0.05 0.05</size>
            </box>
          </geometry>
        </visual>
      </link>
      <link name="link_1">
        <pose>0 0 0.95 0 0 0</pose>
        <inertial>
          <pose>0 0 -0.02 0 0 0</pose>
          <mass>1.0</mass>
          <inertia>
            <ixx>0.0067</ixx>
            <ixy>0.0</ixy>
            <ixz>0.0</ixz>
            <iyy>0.0067</iyy>
            <iyz>0.0</iyz>
            <izz>0.0002</izz>
          </inertia>
        </inertial>
        <collision name="collision">
          <geometry>
            <mesh><uri>model://pipe_link/meshes/pipe_link.stl</uri></mesh>
          </geometry>
        </collision>
        <visual name="visual">
          <geometry>
            <mesh><uri>model://pipe_link/meshes/pipe_link.stl</uri></mesh>
          </geometry>
          <material>
            <script>
              <name>Gazebo/Orange</name>
              <uri>file://media/materials/scripts/gazebo.material</uri>
            </script>
          </material>
        </visual>
      </link>
      <joint name="link_1_joint" type="universal">
        <parent>roof</parent>
        <child>link_1</child>
        <axis>
          <xyz>1 0 0</xyz>
          <limit>
            <lower>-1.57</lower>
            <upper>1.57</upper>
          </limit>
          <dynamics>
            <damping>0.1</damping>
            <friction>0</friction>
            <spring_reference>0</spring_reference>
            <spring_stiffness>0.1</spring_stiffness>
          </dynamics>
          <use_parent_model_frame>true</use_parent_model_frame>
        </axis>
        <axis2>
          <xyz>0 1 0</xyz>
          <limit>
            <lower>-1.57</lower>
            <upper>1.57</upper>
          </limit>
          <dynamics>
            <damping>0.1</damping>
            <friction>0</friction>
            <spring_reference>0</spring_reference>
            <spring_stiffness>0.1</spring_stiffness>
          </dynamics>
          <use_parent_model_frame>true</use_parent_model_frame>
        </axis2>
        <physics>
          <ode>
            <implicit_spring_damper>true</implicit_spring_damper>
            <cfm_damping>true</cfm_damping>
            <limit>
              <cfm>0</cfm>
              <erp>0.2</erp>
            </limit>
          </ode>
        </physics>
      </joint>
      <link name="link_2">
        <pose>0 0 0.91 0 0 0</pose>
        <inertial>
          <pose>0 0 -0.02 0 0 0</pose>
          <mass>1.0</mass>
          <inertia>
            <ixx>0.0067</ixx>
            <ixy>0.0</ixy>
            <ixz>0.0</ixz>
            <iyy>0.0067</iyy>
            <iyz>0.0</iyz>
            <izz>0.0002</izz>
          </inertia>
        </inertial>
        <collision name="collision">
          <geometry>
            <mesh><uri>model://pipe_link/meshes/pipe_link.stl</uri></mesh>
          </geometry>
        </collision>
        <visual name="visual">
          <geometry>
            <mesh><uri>model://pipe_link/meshes/pipe_link.stl</uri></mesh>
          </geometry>
          <material>
            <script>
              <name>Gazebo/Orange</name>
              <uri>file://media/materials/scripts/gazebo.material</uri>
            </script>
          </material>
        </visual>
      </link>
      <joint name="link_2_joint" type="universal">
        <parent>link_1</parent>
        <child>link_2</child>
        <axis>
          <xyz>1 0 0</xyz>
          <limit>
            <lower>-0.524</lower>
            <upper>0.524</upper>
          </limit>
          <dynamics>
            <damping>0.1</damping>
            <friction>0</friction>
            <spring_reference>0</spring_reference>
            <spring_stiffness>0.1</spring_stiffness>
          </dynamics>
          <use_parent_model_frame>true</use_parent_model_frame>
        </axis>
        <axis2>
          <xyz>0 1 0</xyz>
          <limit>
            <lower>-0.524</lower>
            <upper>0.524</upper>
          </limit>
          <dynamics>
            <damping>0.1</damping>
            <friction>0</friction>
            <spring_reference>0</spring_reference>
            <spring_stiffness>0.1</spring_stiffness>
          </dynamics>
          <use_parent_model_frame>true</use_parent_model_frame>
        </axis2>
        <physics>
          <ode>
            <implicit_spring_damper>true</implicit_spring_damper>
            <cfm_damping>true</cfm_damping>
            <limit>
              <cfm>0</cfm>
              <erp>0.2</erp>
            </limit>
          </ode>
        </physics>
      </joint>
      <link name="link_3">
        <pose>0 0 0.87 0 0 0</pose>
        <inertial>
          <pose>0 0 -0.02 0 0 0</pose>
          <mass>1.0</mass>
          <inertia>
            <ixx>0.0067</ixx>
            <ixy>0.0</ixy>
            <ixz>0.0</ixz>
            <iyy>0.0067</iyy>
            <iyz>0.0</iyz>
            <izz>0.0002</izz>
          </inertia>
        </inertial>
        <collision name="collision">
          <geometry>
            <mesh><uri>model://pipe_link/meshes/pipe_link.stl</uri></mesh>
          </geometry>
        </collision>
        <visual name="visual">
          <geometry>
            <mesh><uri>model://pipe_link/meshes/pipe_link.stl</uri></mesh>
          </geometry>
          <material>
            <script>
              <name>Gazebo/Orange</name>
              <uri>file://media/materials/scripts/gazebo.material</uri>
            </script>
          </material>
        </visual>
      </link>
      <joint name="link_3_joint" type="universal">
        <parent>link_2</parent>
        <child>link_3</child>
        <axis>
          <xyz>1 0 0</xyz>
          <limit>
            <lower>-0.524</lower>
            <upper>0.524</upper>
          </limit>
          <dynamics>
            <damping>0.1</damping>
            <friction>0</friction>
            <spring_reference>0</spring_reference>
            <spring_stiffness>0.1</spring_stiffness>
          </dynamics>
          <use_parent_model_frame>true</use_parent_model_frame>
        </axis>
        <axis2>
          <xyz>0 1 0</xyz>
          <limit>
            <lower>-0.524</lower>
            <upper>0.524</upper>
          </limit>
          <dynamics>
            <damping>0.1</damping>
            <friction>0</friction>
            <spring_reference>0</spring_reference>
            <spring_stiffness>0.1</spring_stiffness>
          </dynamics>
          <use_parent_model_frame>true</use_parent_model_frame>
        </axis2>
        <physics>
          <ode>
            <implicit_spring_damper>true</implicit_spring_damper>
            <cfm_damping>true</cfm_damping>
            <limit>
              <cfm>0</cfm>
              <erp>0.2</erp>
            </limit>
          </ode>
        </physics>
      </joint>
      <link name="link_4">
        <pose>0 0 0.83 0 0 0</pose>
        <inertial>
          <pose>0 0 -0.02 0 0 0</pose>
          <mass>1.0</mass>
          <inertia>
            <ixx>0.0067</ixx>
            <ixy>0.0</ixy>
            <ixz>0.0</ixz>
            <iyy>0.0067</iyy>
            <iyz>0.0</iyz>
            <izz>0.0002</izz>
          </inertia>
        </inertial>
        <collision name="collision">
          <geometry>
            <mesh><uri>model://pipe_link/meshes/pipe_link.stl</uri></mesh>
          </geometry>
        </collision>
        <visual name="visual">
          <geometry>
            <mesh><uri>model://pipe_link/meshes/pipe_link.stl</uri></mesh>
          </geometry>
          <material>
            <script>
              <name>Gazebo/Orange</name>
              <uri>file://media/materials/scripts/gazebo.material</uri>
            </script>
          </material>
        </visual>
      </link>
      <joint name="link_4_joint" type="universal">
        <parent>link_3</parent>
        <child>link_4</child>
        <axis>
          <xyz>1 0 0</xyz>
          <limit>
            <lower>-0.524</lower>
            <upper>0.524</upper>
          </limit>
          <dynamics>
            <damping>0.1</damping>
            <friction>0</friction>
            <spring_reference>0</spring_reference>
            <spring_stiffness>0.1</spring_stiffness>
          </dynamics>
          <use_parent_model_frame>true</use_parent_model_frame>
        </axis>
        <axis2>
          <xyz>0 1 0</xyz>
          <limit>
            <lower>-0.524</lower>
            <upper>0.524</upper>
          </limit>
          <dynamics>
            <damping>0.1</damping>
            <friction>0</friction>
            <spring_reference>0</spring_reference>
            <spring_stiffness>0.1</spring_stiffness>
          </dynamics>
          <use_parent_model_frame>true</use_parent_model_frame>
        </axis2>
        <physics>
          <ode>
            <implicit_spring_damper>true</implicit_spring_damper>
            <cfm_damping>true</cfm_damping>
            <limit>
              <cfm>0</cfm>
              <erp>0.2</erp>
            </limit>
          </ode>
        </physics>
      </joint>
      <link name="link_5">
        <pose>0 0 0.79 0 0 0</pose>
        <inertial>
          <pose>0 0 -0.02 0 0 0</pose>
          <mass>1.0</mass>
          <inertia>
            <ixx>0.0067</ixx>
            <ixy>0.0</ixy>
            <ixz>0.0</ixz>
            <iyy>0.0067</iyy>
            <iyz>0.0</iyz>
            <izz>0.0002</izz>
          </inertia>
        </inertial>
        <collision name="collision">
          <geometry>
            <mesh><uri>model://pipe_link/meshes/pipe_link.stl</uri></mesh>
          </geometry>
        </collision>
        <visual name="visual">
          <geometry>
            <mesh><uri>model://pipe_link/meshes/pipe_link.stl</uri></mesh>
          </geometry>
          <material>
            <script>
              <name>Gazebo/Orange</name>
              <uri>file://media/materials/scripts/gazebo.material</uri>
            </script>
          </material>
        </visual>
      </link>
      <joint name="link_5_joint" type="universal">
        <parent>link_4</parent>
        <child>link_5</child>
        <axis>
          <xyz>1 0 0</xyz>
          <limit>
            <lower>-0.524</lower>
            <upper>0.524</upper>
          </limit>
          <dynamics>
            <damping>0.1</damping>
            <friction>0</friction>
            <spring_reference>0</spring_reference>
            <spring_stiffness>0.1</spring_stiffness>
          </dynamics>
          <use_parent_model_frame>true</use_parent_model_frame>
        </axis>
        <axis2>
          <xyz>0 1 0</xyz>
          <limit>
            <lower>-0.524</lower>
            <upper>0.524</upper>
          </limit>
          <dynamics>
            <damping>0.1</damping>
            <friction>0</friction>
            <spring_reference>0</spring_reference>
            <spring_stiffness>0.1</spring_stiffness>
          </dynamics>
          <use_parent_model_frame>true</use_parent_model_frame>
        </axis2>
        <physics>
          <ode>
            <implicit_spring_damper>true</implicit_spring_damper>
            <cfm_damping>true</cfm_damping>
            <limit>
              <cfm>0</cfm>
              <erp>0.2</erp>
            </limit>
          </ode>
        </physics>
      </joint>
      <link name="link_6">
        <pose>0 0 0.75 0 0 0</pose>
        <inertial>
          <pose>0 0 -0.02 0 0 0</pose>
          <mass>1.0</mass>
          <inertia>
            <ixx>0.0067</ixx>
            <ixy>0.0</ixy>
            <ixz>0.0</ixz>
            <iyy>0.0067</iyy>
            <iyz>0.0</iyz>
            <izz>0.0002</izz>
          </inertia>
        </inertial>
        <collision name="collision">
          <geometry>
            <mesh><uri>model://pipe_link/meshes/pipe_link.stl</uri></mesh>
          </geometry>
        </collision>
        <visual name="visual">
          <geometry>
            <mesh><uri>model://pipe_link/meshes/pipe_link.stl</uri></mesh>
          </geometry>
          <material>
            <script>
              <name>Gazebo/Orange</name>
              <uri>file://media/materials/scripts/gazebo.material</uri>
            </script>
          </material>
        </visual>
      </link>
      <joint name="link_6_joint" type="universal">
        <parent>link_5</parent>
        <child>link_6</child>
        <axis>
          <xyz>1 0 0</xyz>
          <limit>
            <lower>-0.524</lower>
            <upper>0.524</upper>
          </limit>
          <dynamics>
            <damping>0.1</damping>
            <friction>0</friction>
            <spring_reference>0</spring_reference>
            <spring_stiffness>0.1</spring_stiffness>
          </dynamics>
          <use_parent_model_frame>true</use_parent_model_frame>
        </axis>
        <axis2>
          <xyz>0 1 0</xyz>
          <limit>
            <lower>-0.524</lower>
            <upper>0.524</upper>
          </limit>
          <dynamics>
            <damping>0.1</damping>
            <friction>0</friction>
            <spring_reference>0</spring_reference>
            <spring_stiffness>0.1</spring_stiffness>
          </dynamics>
          <use_parent_model_frame>true</use_parent_model_frame>
        </axis2>
        <physics>
          <ode>
            <implicit_spring_damper>true</implicit_spring_damper>
            <cfm_damping>true</cfm_damping>
            <limit>
              <cfm>0</cfm>
              <erp>0.2</erp>
            </limit>
          </ode>
        </physics>
      </joint>
      <link name="link_7">
        <pose>0 0 0.71 0 0 0</pose>
        <inertial>
          <pose>0 0 -0.02 0 0 0</pose>
          <mass>1.0</mass>
          <inertia>
            <ixx>0.0067</ixx>
            <ixy>0.0</ixy>
            <ixz>0.0</ixz>
            <iyy>0.0067</iyy>
            <iyz>0.0</iyz>
            <izz>0.0002</izz>
          </inertia>
        </inertial>
        <collision name="collision">
          <geometry>
            <mesh><uri>model://pipe_link/meshes/pipe_link.stl</uri></mesh>
          </geometry>
        </collision>
        <visual name="visual">
          <geometry>
            <mesh><uri>model://pipe_link/meshes/pipe_link.stl</uri></mesh>
          </geometry>
          <material>
            <script>
              <name>Gazebo/Orange</name>
              <uri>file://media/materials/scripts/gazebo.material</uri>
            </script>
          </material>
        </visual>
      </link>
      <joint name="link_7_joint" type="universal">
        <parent>link_6</parent>
        <child>link_7</child>
        <axis>
          <xyz>1 0 0</xyz>
          <limit>
            <lower>-0.524</lower>
            <upper>0.524</upper>
          </limit>
          <dynamics>
            <damping>0.1</damping>
            <friction>0</friction>
            <spring_reference>0</spring_reference>
            <spring_stiffness>0.1</spring_stiffness>
          </dynamics>
          <use_parent_model_frame>true</use_parent_model_frame>
        </axis>
        <axis2>
          <xyz>0 1 0</xyz>
          <limit>
            <lower>-0.524</lower>
            <upper>0.524</upper>
          </limit>
          <dynamics>
            <damping>0.1</damping>
            <friction>0</friction>
            <spring_reference>0</spring_reference>
            <spring_stiffness>0.1</spring_stiffness>
          </dynamics>
          <use_parent_model_frame>true</use_parent_model_frame>
        </axis2>
        <physics>
          <ode>
            <implicit_spring_damper>true</implicit_spring_damper>
            <cfm_damping>true</cfm_damping>
            <limit>
              <cfm>0</cfm>
              <erp>0.2</erp>
            </limit>
          </ode>
        </physics>
      </joint>
      <link name="link_8">
        <pose>0 0 0.67 0 0 0</pose>
        <inertial>
          <pose>0 0 -0.02 0 0 0</pose>
          <mass>1.0</mass>
          <inertia>
            <ixx>0.0067</ixx>
            <ixy>0.0</ixy>
            <ixz>0.0</ixz>
            <iyy>0.0067</iyy>
            <iyz>0.0</iyz>
            <izz>0.0002</izz>
          </inertia>
        </inertial>
        <collision name="collision">
          <geometry>
            <mesh><uri>model://pipe_link/meshes/pipe_link.stl</uri></mesh>
          </geometry>
        </collision>
        <visual name="visual">
          <geometry>
            <mesh><uri>model://pipe_link/meshes/pipe_link.stl</uri></mesh>
          </geometry>
          <material>
            <script>
              <name>Gazebo/Orange</name>
              <uri>file://media/materials/scripts/gazebo.material</uri>
            </script>
          </material>
        </visual>
      </link>
      <joint name="link_8_joint" type="universal">
        <parent>link_7</parent>
        <child>link_8</child>
        <axis>
          <xyz>1 0 0</xyz>
          <limit>
            <lower>-0.524</lower>
            <upper>0.524</upper>
          </limit>
          <dynamics>
            <damping>0.1</damping>
            <friction>0</friction>
            <spring_reference>0</spring_reference>
            <spring_stiffness>0.1</spring_stiffness>
          </dynamics>
          <use_parent_model_frame>true</use_parent_model_frame>
        </axis>
        <axis2>
          <xyz>0 1 0</xyz>
          <limit>
            <lower>-0.524</lower>
            <upper>0.524</upper>
          </limit>
          <dynamics>
            <damping>0.1</damping>
            <friction>0</friction>
            <spring_reference>0</spring_reference>
            <spring_stiffness>0.1</spring_stiffness>
          </dynamics>
          <use_parent_model_frame>true</use_parent_model_frame>
        </axis2>
        <physics>
          <ode>
            <implicit_spring_damper>true</implicit_spring_damper>
            <cfm_damping>true</cfm_damping>
            <limit>
              <cfm>0</cfm>
              <erp>0.2</erp>
            </limit>
          </ode>
        </physics>
      </joint>
      <link name="link_9">
        <pose>0 0 0.63 0 0 0</pose>
        <inertial>
          <pose>0 0 -0.02 0 0 0</pose>
          <mass>1.0</mass>
          <inertia>
            <ixx>0.0067</ixx>
            <ixy>0.0</ixy>
            <ixz>0.0</ixz>
            <iyy>0.0067</iyy>
            <iyz>0.0</iyz>
            <izz>0.0002</izz>
          </inertia>
        </inertial>
        <collision name="collision">
          <geometry>
            <mesh><uri>model://pipe_link/meshes/pipe_link.stl</uri></mesh>
          </geometry>
        </collision>
        <visual name="visual">
          <geometry>
            <mesh><uri>model://pipe_link/meshes/pipe_link.stl</uri></mesh>
          </geometry>
          <material>
            <script>
              <name>Gazebo/Orange</name>
              <uri>file://media/materials/scripts/gazebo.material</uri>
            </script>
          </material>
        </visual>
      </link>
      <joint name="link_9_joint" type="universal">
        <parent>link_8</parent>
        <child>link_9</child>
        <axis>
          <xyz>1 0 0</xyz>
          <limit>
            <lower>-0.524</lower>
            <upper>0.524</upper>
          </limit>
          <dynamics>
            <damping>0.1</damping>
            <friction>0</friction>
            <spring_reference>0</spring_reference>
            <spring_stiffness>0.1</spring_stiffness>
          </dynamics>
          <use_parent_model_frame>true</use_parent_model_frame>
        </axis>
        <axis2>
          <xyz>0 1 0</xyz>
          <limit>
            <lower>-0.524</lower>
            <upper>0.524</upper>
          </limit>
          <dynamics>
            <damping>0.1</damping>
            <friction>0</friction>
            <spring_reference>0</spring_reference>
            <spring_stiffness>0.1</spring_stiffness>
          </dynamics>
          <use_parent_model_frame>true</use_parent_model_frame>
        </axis2>
        <physics>
          <ode>
            <implicit_spring_damper>true</implicit_spring_damper>
            <cfm_damping>true</cfm_damping>
            <limit>
              <cfm>0</cfm>
              <erp>0.2</erp>
            </limit>
          </ode>
        </physics>
      </joint>
      <link name="link_10">
        <pose>0 0 0.59 0 0 0</pose>
        <inertial>
          <pose>0 0 -0.02 0 0 0</pose>
          <mass>1.0</mass>
          <inertia>
            <ixx>0.0067</ixx>
            <ixy>0.0</ixy>
            <ixz>0.0</ixz>
            <iyy>0.0067</iyy>
            <iyz>0.0</iyz>
            <izz>0.0002</izz>
          </inertia>
        </inertial>
        <collision name="collision">
          <geometry>
            <mesh><uri>model://pipe_link/meshes/pipe_link.stl</uri></mesh>
          </geometry>
        </collision>
        <visual name="visual">
          <geometry>
            <mesh><uri>model://pipe_link/meshes/pipe_link.stl</uri></mesh>
          </geometry>
          <material>
            <script>
              <name>Gazebo/Orange</name>
              <uri>file://media/materials/scripts/gazebo.material</uri>
            </script>
          </material>
        </visual>
      </link>
      <joint name="link_10_joint" type="universal">
        <parent>link_9</parent>
        <child>link_10</child>
        <axis>
          <xyz>1 0 0</xyz>
          <limit>
            <lower>-0.524</lower>
            <upper>0.524</upper>
          </limit>
          <dynamics>
            <damping>0.1</damping>
            <friction>0</friction>
            <spring_reference>0</spring_reference>
            <spring_stiffness>0.1</spring_stiffness>
          </dynamics>
          <use_parent_model_frame>true</use_parent_model_frame>
        </axis>
        <axis2>
          <xyz>0 1 0</xyz>
          <limit>
            <lower>-0.524</lower>
            <upper>0.524</upper>
          </limit>
          <dynamics>
            <damping>0.1</damping>
            <friction>0</friction>
            <spring_reference>0</spring_reference>
            <spring_stiffness>0.1</spring_stiffness>
          </dynamics>
          <use_parent_model_frame>true</use_parent_model_frame>
        </axis2>
        <physics>
          <ode>
            <implicit_spring_damper>true</implicit_spring_damper>
            <cfm_damping>true</cfm_damping>
            <limit>
              <cfm>0</cfm>
              <erp>0.2</erp>
            </limit>
          </ode>
        </physics>
      </joint>
      <plugin name="DeformablePipePlugin" filename="libdeformable_pipe_plugin.so"/>
    </model>

    <wind>
      <linear_velocity>0 0 0</linear_velocity>
    </wind>

    <!-- Load the plugin for the wind -->

    <plugin name="wind" filename="libWindPlugin.so">
      <horizontal>
        <magnitude>
          <time_for_rise>10</time_for_rise>
          <sin>
            <amplitude_percent>0.05</amplitude_percent>
            <period>60</period>
          </sin>
          <noise type="gaussian">
           <mean>0</mean>
           <stddev>0.0002</stddev>
          </noise>
        </magnitude>
        <direction>
          <time_for_rise>30</time_for_rise>
          <sin>
            <amplitude>60</amplitude>
            <period>5</period>
          </sin>
          <noise type="gaussian">
           <mean>0</mean>
           <stddev>0.03</stddev>
          </noise>
        </direction>
      </horizontal>
      <vertical>
        <noise type="gaussian">
         <mean>0</mean>
         <stddev>0.03</stddev>
        </noise>
      </vertical>
    </plugin>

    <plugin name="RealTimeFactorPlugin" filename="libreal_time_factor_plugin.so"/>
  </world>
</sdf>
